Workbook

Sheet wikily_maps
A1: Column1 | B1: aberration | C1: astraeos | D1: crystal-isles | E1: extinction | F1: fjordur | G1: genesis-2 | H1: genesis | I1: lost-island | J1: ragnarok | K1: scorched-earth | L1: the-center | M1: the-island | N1: valguero | O1: Zusammengeführt
A2: Aberrant Achatina | B2: Aberration | F2: Fjordur | O2: Aberration, Fjordur
A3: Aberrant Anglerfish | B3: Aberration | D3: Crystal Isles | N3: Valguero | O3: Aberration, Crystal Isles, Valguero
A4: Aberrant Ankylosaurus | B4: Aberration | O4: Aberration
A5: Aberrant Araneo | B5: Aberration | N5: Valguero | O5: Aberration, Valguero
A6: Aberrant Arthropluera | B6: Aberration | D6: Crystal Isles | F6: Fjordur | I6: Lost Island | O6: Aberration, Crystal Isles, Fjordur, Lost Island
A7: Aberrant Baryonyx | B7: Aberration | D7: Crystal Isles | N7: Valguero | O7: Aberration, Crystal Isles, Valguero
A8: Aberrant Beelzebufo | B8: Aberration | D8: Crystal Isles | N8: Valguero | O8: Aberration, Crystal Isles, Valguero
A9: Aberrant Carbonemys | B9: Aberration | C9: Astraeos | F9: Fjordur | N9: Valguero | O9: Aberration, Astraeos, Fjordur, Valguero
A10: Aberrant Carnotaurus | B10: Aberration | C10: Astraeos | D10: Crystal Isles | F10: Fjordur | I10: Lost Island | N10: Valguero | O10: Aberration, Astraeos, Crystal Isles, Fjordur, Lost Island, Valguero
A11: Aberrant Cnidaria | B11: Aberration | C11: Astraeos | D11: Crystal Isles | O11: Aberration, Astraeos, Crystal Isles
A12: Aberrant Coelacanth | B12: Aberration | C12: Astraeos | D12: Crystal Isles | F12: Fjordur | O12: Aberration, Astraeos, Crystal Isles, Fjordur
A13: Aberrant Dimetrodon | B13: Aberration | D13: Crystal Isles | N13: Valguero | O13: Aberration, Crystal Isles, Valguero
A14: Aberrant Dimorphodon | B14: Aberration | N14: Valguero | O14: Aberration, Valguero
A15: Aberrant Diplocaulus | B15: Aberration | D15: Crystal Isles | N15: Valguero | O15: Aberration, Crystal Isles, Valguero
A16: Aberrant Diplodocus | B16: Aberration | C16: Astraeos | F16: Fjordur | N16: Valguero | O16: Aberration, Astraeos, Fjordur, Valguero
A17: Aberrant Dire Bear | B17: Aberration | C17: Astraeos | F17: Fjordur | N17: Valguero | O17: Aberration, Astraeos, Fjordur, Valguero
A18: Aberrant Dodo | B18: Aberration | C18: Astraeos | F18: Fjordur | J18: Ragnarok | N18: Valguero | O18: Aberration, Astraeos, Fjordur, Ragnarok, Valguero
A19: Aberrant Doedicurus | B19: Aberration | C19: Astraeos | F19: Fjordur | N19: Valguero | O19: Aberration, Astraeos, Fjordur, Valguero
A20: Aberrant Dung Beetle | B20: Aberration | D20: Crystal Isles | F20: Fjordur | O20: Aberration, Crystal Isles, Fjordur
A21: Aberrant Electrophorus | B21: Aberration | C21: Astraeos | D21: Crystal Isles | N21: Valguero | O21: Aberration, Astraeos, Crystal Isles, Valguero
A22: Aberrant Equus | B22: Aberration | C22: Astraeos | F22: Fjordur | N22: Valguero | O22: Aberration, Astraeos, Fjordur, Valguero
A23: Aberrant Fasolasuchus | B23: Aberration | O23: Aberration
A24: Aberrant Gigantopithecus | B24: Aberration | O24: Aberration
A25: Aberrant Gigantoraptor | B25: Aberration | C25: Astraeos | O25: Aberration, Astraeos
A26: Aberrant Iguanodon | B26: Aberration | C26: Astraeos | F26: Fjordur | N26: Valguero | O26: Aberration, Astraeos, Fjordur, Valguero
A27: Aberrant Lystrosaurus | B27: Aberration | C27: Astraeos | F27: Fjordur | N27: Valguero | O27: Aberration, Astraeos, Fjordur, Valguero
A28: Aberrant Manta | B28: Aberration | D28: Crystal Isles | O28: Aberration, Crystal Isles
A29: Aberrant Megalania | B29: Aberration | F29: Fjordur | J29: Ragnarok | O29: Aberration, Fjordur, Ragnarok
A30: Aberrant Megalosaurus | B30: Aberration | D30: Crystal Isles | F30: Fjordur | O30: Aberration, Crystal Isles, Fjordur
A31: Aberrant Meganeura | B31: Aberration | C31: Astraeos | F31: Fjordur | I31: Lost Island | N31: Valguero | O31: Aberration, Astraeos, Fjordur, Lost Island, Valguero
A32: Aberrant Moschops | B32: Aberration | C32: Astraeos | F32: Fjordur | N32: Valguero | O32: Aberration, Astraeos, Fjordur, Valguero
A33: Aberrant Otter | B33: Aberration | C33: Astraeos | D33: Crystal Isles | F33: Fjordur | N33: Valguero | O33: Aberration, Astraeos, Crystal Isles, Fjordur, Valguero
A34: Aberrant Oviraptor | B34: Aberration | C34: Astraeos | O34: Aberration, Astraeos
A35: Aberrant Ovis | B35: Aberration | C35: Astraeos | F35: Fjordur | N35: Valguero | O35: Aberration, Astraeos, Fjordur, Valguero
A36: Aberrant Paraceratherium | B36: Aberration | C36: Astraeos | F36: Fjordur | N36: Valguero | O36: Aberration, Astraeos, Fjordur, Valguero
A37: Aberrant Parasaur | B37: Aberration | C37: Astraeos | F37: Fjordur | N37: Valguero | O37: Aberration, Astraeos, Fjordur, Valguero
A38: Aberrant Piranha | B38: Aberration | C38: Astraeos | D38: Crystal Isles | F38: Fjordur | O38: Aberration, Astraeos, Crystal Isles, Fjordur
A39: Aberrant Pulmonoscorpius | B39: Aberration | C39: Astraeos | D39: Crystal Isles | F39: Fjordur | I39: Lost Island | N39: Valguero | O39: Aberration, Astraeos, Crystal Isles, Fjordur, Lost Island, Valguero
A40: Aberrant Purlovia | B40: Aberration | D40: Crystal Isles | F40: Fjordur | O40: Aberration, Crystal Isles, Fjordur
...

Sheet Tabelle2
A1: Creature | B1: Varianten | C1: Boss | D1: Maps | E1: Health | F1: Health | G1: Health | H1: Stamina | I1: Stamina | J1: Stamina | K1: Oxygen | L1: Oxygen | M1: Oxygen | N1: Food | O1: Food | P1: Food | Q1: Weight | R1: Weight | S1: Weight | T1: Melee Damage | U1: Melee Damage | V1: Melee Damage | W1: Movement Speed | X1: Movement Speed | Y1: Torpidity | Z1: Torpidity
E2: Base | F2: +Wild | G2: +Tame | H2: Base | I2: +Wild | J2: +Tame | K2: Base | L2: +Wild | M2: +Tame | N2: Base | O2: +Wild | P2: +Tame | Q2: Base | R2: +Wild | S2: +Tame | T2: Base | U2: +Wild | V2: +Tame | W2: Base | X2: +Tame | Y2: Base | Z2: +Wild | AB2: Level 1 | AC2: Level 150
A3: Achatina | D3: =VLOOKUP(TRIM(A3),wikily_maps!A:O,15,FALSE) -> Astraeos, Crystal Isles, Extinction, Fjordur, Genesis 2, Lost Island, Ragnarok, Scorched Earth, The Center, The Island, Valguero | E3: 75 | F3: 15 | G3: 5.4 | H3: 100 | I3: 10 | J3: 10 | K3: 0 | L3: 0 | M3: 0 | N3: 450 | O3: 45 | P3: 10 | Q3: 150 | R3: 3 | S3: 4 | T3: 1 | U3: 0.05 | V3: 1.7 | W3: 100 | X3: 1 | Y3: 50 | Z3: 3 | AB3: =$N3+($O3*1) -> 495 | AC3: =$N3+($O3*150) -> 7200
A4: Allosaurus | D4: =VLOOKUP(TRIM(A4),wikily_maps!A:O,15,FALSE) -> Astraeos, Crystal Isles, Extinction, Fjordur, Genesis 2, Lost Island, Ragnarok, The Center, The Island, Valguero | E4: 630 | F4: 126 | G4: 5.4 | H4: 250 | I4: 25 | J4: 10 | K4: 150 | L4: 15 | M4: 10 | N4: 3000 | O4: 300 | P4: 10 | Q4: 380 | R4: 7.6 | S4: 4 | T4: 35 | U4: 1.75 | V4: 1.7 | W4: 100 | X4: 1 | Y4: 1000 | Z4: 60
A5: Amargasaurus | D5: =VLOOKUP(TRIM(A5),wikily_maps!A:O,15,FALSE) -> Lost Island | E5: 1250 | F5: 250 | G5: 5.4 | H5: 425 | I5: 42.5 | J5: 10 | K5: 300 | L5: 30 | M5: 10 | N5: 6300 | O5: 630 | P5: 10 | Q5: 475 | R5: 9.5 | S5: 4 | T5: 40 | U5: 2 | V5: 1.7 | W5: 100 | X5: 1 | Y5: 2250 | Z5: 135
A6: Ammonite | D6: =VLOOKUP(TRIM(A6),wikily_maps!A:O,15,FALSE) -> Astraeos, Crystal Isles, Fjordur, Genesis 2, Genesis, Lost Island, Ragnarok, The Center, The Island, Valguero | E6: 165 | F6: 33 | G6: 5.4 | H6: 100 | I6: 10 | J6: 10 | K6: 0 | L6: 0 | M6: 0 | N6: 450 | O6: 45 | P6: 10 | Q6: 150 | R6: 3 | S6: 4 | T6: 10 | U6: 0.5 | V6: 1.7 | W6: 100 | X6: 0 | Y6: 50 | Z6: 3
A7: Andrewsarchus | D7: =VLOOKUP(TRIM(A7),wikily_maps!A:O,15,FALSE) -> Fjordur | E7: 800 | F7: 160 | G7: 5.4 | H7: 400 | I7: 40 | J7: 10 | K7: 650 | L7: 65 | M7: 10 | N7: 2174 | O7: 217.4 | P7: 10 | Q7: 500 | R7: 10 | S7: 4 | T7: 41 | U7: 2.05 | V7: 1.7 | W7: 100 | X7: 0.5 | Y7: 800 | Z7: 48
A8: Anglerfish | D8: =VLOOKUP(TRIM(A8),wikily_maps!A:O,15,FALSE) -> Astraeos, Crystal Isles, Fjordur, Genesis 2, Genesis, Lost Island, Ragnarok, The Center, The Island, Valguero | E8: 450 | F8: 90 | G8: 5.4 | H8: 240 | I8: 24 | J8: 10 | K8: 150 | L8: 15 | M8: 0 | N8: 1500 | O8: 150 | P8: 10 | Q8: 350 | R8: 7 | S8: 4 | T8: 30 | U8: 1.5 | V8: 1.7 | W8: 100 | X8: 1 | Y8: 900 | Z8: 54
A9: Ankylosaurus | D9: =VLOOKUP(TRIM(A9),wikily_maps!A:O,15,FALSE) -> Astraeos, Crystal Isles, Extinction, Fjordur, Genesis 2, Genesis, Lost Island, Ragnarok, Scorched Earth, The Center, The Island, Valguero | E9: 700 | F9: 140 | G9: 5.4 | H9: 175 | I9: 17.5 | J9: 10 | K9: 150 | L9: 15 | M9: 10 | N9: 3000 | O9: 300 | P9: 10 | Q9: 250 | R9: 5 | S9: 4 | T9: 50 | U9: 2.5 | V9: 1.7 | W9: 100 | X9: 2 | Y9: 420 | Z9: 25.2
A10: Araneo | D10: =VLOOKUP(TRIM(A10),wikily_maps!A:O,15,FALSE) -> Astraeos, Crystal Isles, Extinction, Fjordur, Genesis 2, Genesis, Lost Island, Ragnarok, Scorched Earth, The Center, The Island, Valguero | E10: 150 | F10: 30 | G10: 2.7 | H10: 100 | I10: 10 | J10: 10 | K10: 150 | L10: 15 | M10: 10 | N10: 900 | O10: 90 | P10: 10 | Q10: 100 | R10: 2 | S10: 8 | T10: 10 | U10: 0.5 | V10: 1.7 | W10: 100 | X10: 1 | Y10: 80 | Z10: 4.8
A11: Archaeopteryx | D11: =VLOOKUP(TRIM(A11),wikily_maps!A:O,15,FALSE) -> Crystal Isles, Extinction, Fjordur, Genesis, Lost Island, Ragnarok, Scorched Earth, The Center, The Island, Valguero | E11: 125 | F11: 25 | G11: 5.4 | H11: 150 | I11: 15 | J11: 10 | K11: 150 | L11: 15 | M11: 10 | N11: 900 | O11: 90 | P11: 10 | Q11: 30 | R11: 0.6 | S11: 4 | T11: 5 | U11: 0.25 | V11: 1.7 | W11: 100 | X11: 1 | Y11: 100 | Z11: 6
A12: Archelon | D12: =VLOOKUP(TRIM(A12),wikily_maps!A:O,15,FALSE) -> Astraeos, Ragnarok, The Center, The Island, Valguero | E12: 1400 | F12: 280 | G12: 2.5 | H12: 775 | I12: 77.5 | J12: 10 | K12: 0 | L12: 0 | M12: 0 | N12: 3500 | O12: 350 | P12: 10 | Q12: 1000 | R12: 20 | S12: 4 | T12: 28 | U12: 1.4 | V12: 1.7 | W12: 100 | X12: 2 | Y12: 2000 | Z12: 120
A13: Argentavis | D13: =VLOOKUP(TRIM(A13),wikily_maps!A:O,15,FALSE) -> Astraeos, Crystal Isles, Extinction, Fjordur, Genesis 2, Genesis, Lost Island, Ragnarok, Scorched Earth, The Center, The Island, Valguero | E13: 365 | F13: 73 | G13: 6 | H13: 400 | I13: 20 | J13: 7.5 | K13: 150 | L13: 15 | M13: 10 | N13: 2000 | O13: 200 | P13: 10 | Q13: 400 | R13: 8 | S13: 5.5 | T13: 25 | U13: 1.25 | V13: 2.55 | W13: 100 | X13: 0 | Y13: 600 | Z13: 36
A14: Armadoggo | D14: =VLOOKUP(TRIM(A14),wikily_maps!A:O,15,FALSE) -> Extinction | E14: 200 | F14: 40 | G14: 5.4 | H14: 260 | I14: 26 | J14: 10 | K14: 150 | L14: 15 | M14: 10 | N14: 1200 | O14: 120 | P14: 10 | Q14: 200 | R14: 4 | S14: 4 | T14: 15 | U14: 0.75 | V14: 1.7 | W14: 100 | X14: 2.5 | Y14: 450 | Z14: 27
A15: Arthropluera | D15: =VLOOKUP(TRIM(A15),wikily_maps!A:O,15,FALSE) -> Astraeos, Crystal Isles, Extinction, Fjordur, Genesis 2, Genesis, Lost Island, Ragnarok, Scorched Earth, The Center, The Island, Valguero | E15: 500 | F15: 100 | G15: 5.4 | H15: 200 | I15: 20 | J15: 10 | K15: 0 | L15: 0 | M15: 0 | N15: 1200 | O15: 120 | P15: 10 | Q15: 100 | R15: 2 | S15: 4 | T15: 18 | U15: 0.9 | V15: 1.7 | W15: 100 | X15: 1 | Y15: 175 | Z15: 10.5
... A17: Astrodelphis | D17: =VLOOKUP(TRIM(A17),wikily_maps!A:O,15,FALSE) -> Genesis 2 | E17: 325 | F17: 65 | G17: 5.4 | H17: 250 | I17: 12.5 | J17: 6 | K17: 150 | L17: 15 | M17: 10 | N17: 1600 | O17: 160 | P17: 10 | Q17: 280 | R17: 5.6 | S17: 4 | T17: 24 | U17: 1.2 | V17: 1.7 | W17: 100 | X17: 1 | Y17: 450 | Z17: 27
A18: Attack Drone | B18: Gamma | C18: Overseer Gamma | D18: The Island | E18: 145.8 | F18: 0 | G18: 0 | H18: 250 | I18: 0 | J18: 0 | K18: 150 | L18: 0 | M18: 0 | N18: 1600 | O18: 0 | P18: 0 | Q18: 280 | R18: 0 | S18: 0 | T18: 280 | U18: 0 | V18: 0 | W18: 100 | X18: 0 | Y18: 450 | Z18: 0
A19: Attack Drone | B19: Beta | C19: Overseer Beta | D19: The Island | E19: 585 | F19: 0 | G19: 0 | H19: 250 | I19: 0 | J19: 0 | K19: 150 | L19: 0 | M19: 0 | N19: 1600 | O19: 0 | P19: 0 | Q19: 280 | R19: 0 | S19: 0 | T19: 280 | U19: 0 | V19: 0 | W19: 100 | X19: 0 | Y19: 450 | Z19: 0
A20: Attack Drone | B20: Alpha | C20: Overseer Alpha | D20: The Island | E20: 877.5 | F20: 0 | G20: 0 | H20: 250 | I20: 0 | J20: 0 | K20: 150 | L20: 0 | M20: 0 | N20: 1600 | O20: 0 | P20: 0 | Q20: 280 | R20: 0 | S20: 0 | T20: 280 | U20: 0 | V20: 0 | W20: 100 | X20: 0 | Y20: 450 | Z20: 0
A21: Attack Drone | B21: Gamma | C21: Overseer Gamma | D21: The Island | E21: 145.8 | F21: 0 | G21: 0 | H21: 250 | I21: 0 | J21: 0 | K21: 150 | L21: 0 | M21: 0 | N21: 1600 | O21: 0 | P21: 0 | Q21: 280 | R21: 0 | S21: 0 | T21: 280 | U21: 0 | V21: 0 | W21: 100 | X21: 0 | Y21: 450 | Z21: 0
A22: Attack Drone | B22: Beta | C22: Overseer Beta | D22: The Island | E22: 585 | F22: 0 | G22: 0 | H22: 250 | I22: 0 | J22: 0 | K22: 150 | L22: 0 | M22: 0 | N22: 1600 | O22: 0 | P22: 0 | Q22: 280 | R22: 0 | S22: 0 | T22: 280 | U22: 0 | V22: 0 | W22: 100 | X22: 0 | Y22: 450 | Z22: 0
A23: Attack Drone | B23: Alpha | C23: Overseer Alpha | D23: The Island | E23: 877.5 | F23: 0 | G23: 0 | H23: 250 | I23: 0 | J23: 0 | K23: 150 | L23: 0 | M23: 0 | N23: 1600 | O23: 0 | P23: 0 | Q23: 280 | R23: 0 | S23: 0 | T23: 280 | U23: 0 | V23: 0 | W23: 100 | X23: 0 | Y23: 450 | Z23: 0
A24: Attack Drone | B24: Gamma | C24: Overseer Gamma | D24: The Island | E24: 145.8 | F24: 0 | G24: 0 | H24: 250 | I24: 0 | J24: 0 | K24: 150 | L24: 0 | M24: 0 | N24: 1600 | O24: 0 | P24: 0 | Q24: 280 | R24: 0 | S24: 0 | T24: 280 | U24: 0 | V24: 0 | W24: 100 | X24: 0 | Y24: 450 | Z24: 0
A25: Attack Drone | B25: Beta | C25: Overseer Beta | D25: The Island | E25: 585 | F25: 0 | G25: 0 | H25: 250 | I25: 0 | J25: 0 | K25: 150 | L25: 0 | M25: 0 | N25: 1600 | O25: 0 | P25: 0 | Q25: 280 | R25: 0 | S25: 0 | T25: 280 | U25: 0 | V25: 0 | W25: 100 | X25: 0 | Y25: 450 | Z25: 0
A26: Attack Drone | B26: Alpha | C26: Overseer Alpha | D26: The Island | E26: 877.5 | F26: 0 | G26: 0 | H26: 250 | I26: 0 | J26: 0 | K26: 150 | L26: 0 | M26: 0 | N26: 1600 | O26: 0 | P26: 0 | Q26: 280 | R26: 0 | S26: 0 | T26: 280 | U26: 0 | V26: 0 | W26: 100 | X26: 0 | Y26: 450 | Z26: 0
A27: Attack Drone | B27: Gamma | C27: Overseer Gamma | D27: The Island | E27: 145.8 | F27: 0 | G27: 0 | H27: 250 | I27: 0 | J27: 0 | K27: 150 | L27: 0 | M27: 0 | N27: 1600 | O27: 0 | P27: 0 | Q27: 280 | R27: 0 | S27: 0 | T27: 280 | U27: 0 | V27: 0 | W27: 100 | X27: 0 | Y27: 450 | Z27: 0
A28: Attack Drone | B28: Beta | C28: Overseer Beta | D28: The Island | E28: 585 | F28: 0 | G28: 0 | H28: 250 | I28: 0 | J28: 0 | K28: 150 | L28: 0 | M28: 0 | N28: 1600 | O28: 0 | P28: 0 | Q28: 280 | R28: 0 | S28: 0 | T28: 280 | U28: 0 | V28: 0 | W28: 100 | X28: 0 | Y28: 450 | Z28: 0
A29: Attack Drone | B29: Alpha | C29: Overseer Alpha | D29: The Island | E29: 877.5 | F29: 0 | G29: 0 | H29: 250 | I29: 0 | J29: 0 | K29: 150 | L29: 0 | M29: 0 | N29: 1600 | O29: 0 | P29: 0 | Q29: 280 | R29: 0 | S29: 0 | T29: 280 | U29: 0 | V29: 0 | W29: 100 | X29: 0 | Y29: 450 | Z29: 0
... A32: Attack Drone | B32: Alpha | C32: Overseer Alpha | D32: The Island | E32: 877.5 | F32: 0 | G32: 0 | H32: 250 | I32: 0 | J32: 0 | K32: 150 | L32: 0 | M32: 0 | N32: 1600 | O32: 0 | P32: 0 | Q32: 280 | R32: 0 | S32: 0 | T32: 280 | U32: 0 | V32: 0 | W32: 100 | X32: 0 | Y32: 450 | Z32: 0
A33: Baryonyx | D33: =VLOOKUP(TRIM(A33),wikily_maps!A:O,15,FALSE) -> Astraeos, Crystal Isles, Extinction, Fjordur, Genesis 2, Genesis, Lost Island, Ragnarok, The Center, The Island, Valguero | E33: 440 | F33: 88 | G33: 5.4 | H33: 325 | I33: 32.5 | J33: 10 | K33: 225 | L33: 22.5 | M33: 0 | N33: 2250 | O33: 225 | P33: 10 | Q33: 325 | R33: 6.5 | S33: 4 | T33: 35 | U33: 1.75 | V33: 1.7 | W33: 100 | X33: 1 | Y33: 400 | Z33: 24
A34: Basilisk | D34: =VLOOKUP(TRIM(A34),wikily_maps!A:O,15,FALSE) -> Aberration, Crystal Isles, Fjordur, Genesis 2, Genesis, Lost Island, Valguero | E34: 2750 | F34: 550 | G34: 5.4 | H34: 650 | I34: 65 | J34: 10 | K34: 0 | L34: 0 | M34: 0 | N34: 2500 | O34: 250 | P34: 10 | Q34: 800 | R34: 16 | S34: 4 | T34: 44 | U34: 2.2 | V34: 1.7 | W34: 100 | X34: 1 | Y34: 175 | Z34: 10.5
A35: Basilosaurus | D35: =VLOOKUP(TRIM(A35),wikily_maps!A:O,15,FALSE) -> Crystal Isles, Fjordur, Genesis 2, Lost Island, Ragnarok, The Center, The Island, Valguero | E35: 2400 | F35: 480 | G35: 4.86 | H35: 300 | I35: 30 | J35: 10 | K35: 150 | L35: 15 | M35: 0 | N35: 8000 | O35: 800 | P35: 10 | Q35: 700 | R35: 14 | S35: 4 | T35: 47 | U35: 2.35 | V35: 1.7 | W35: 100 | X35: 1 | Y35: 2000 | Z35: 120
A36: Beelzebufo | D36: =VLOOKUP(TRIM(A36),wikily_maps!A:O,15,FALSE) -> Astraeos, Crystal Isles, Extinction, Fjordur, Genesis 2, Genesis, Lost Island, Ragnarok, The Center, The Island, Valguero | E36: 220 | F36: 44 | G36: 5.4 | H36: 190 | I36: 19 | J36: 10 | K36: 150 | L36: 15 | M36: 0 | N36: 1500 | O36: 150 | P36: 10 | Q36: 160 | R36: 3.2 | S36: 4 | T36: 12 | U36: 0.6 | V36: 1.7 | W36: 100 | X36: 2 | Y36: 200 | Z36: 12
A37: Beyla | B37: Boss | C37: Beyla | D37: Fjordur | E37: 175000 | F37: 0 | G37: 0 | H37: 1250 | I37: 0 | J37: 0 | K37: 300 | L37: 0 | M37: 0 | N37: 1500 | O37: 0 | P37: 0 | Q37: 400 | R37: 0 | S37: 0 | T37: 150 | U37: 0 | V37: 0 | W37: 100 | X37: 0 | Y37: 1500 | Z37: 0
A38: Bison | D38: =VLOOKUP(TRIM(A38),wikily_maps!A:O,15,FALSE) -> Ragnarok, Valguero | E38: 800 | F38: 160 | G38: 5.4 | H38: 500 | I38: 50 | J38: 10 | K38: 150 | L38: 15 | M38: 10 | N38: 3250 | O38: 325 | P38: 10 | Q38: 650 | R38: 13 | S38: 4 | T38: 30 | U38: 1.5 | V38: 1.7 | W38: 100 | X38: 1 | Y38: 500 | Z38: 30
A39: Bloodstalker | D39: =VLOOKUP(TRIM(A39),wikily_maps!A:O,15,FALSE) -> Genesis 2, Genesis | E39: 450 | F39: 90 | G39: 5.4 | H39: 600 | I39: 60 | J39: 10 | K39: 150 | L39: 15 | M39: 10 | N39: 1200 | O39: 120 | P39: 10 | Q39: 350 | R39: 7 | S39: 4 | T39: 26 | U39: 1.3 | V39: 1.7 | W39: 100 | X39: 1.5 | Y39: 180 | Z39: 10.8
A40: Brontosaurus | D40: =VLOOKUP(TRIM(A40),wikily_maps!A:O,15,FALSE) -> Astraeos, Crystal Isles, Extinction, Fjordur, Genesis 2, Genesis, Lost Island, Ragnarok, The Center, The Island, Valguero | E40: 2277 | F40: 455.4 | G40: 2.5 | H40: 240 | I40: 24 | J40: 10 | K40: 150 | L40: 15 | M40: 10 | N40: 10000 | O40: 1000 | P40: 10 | Q40: 1600 | R40: 32 | S40: 4 | T40: 60 | U40: 3 | V40: 1.7 | W40: 100 | X40: 2 | Y40: 2000 | Z40: 120
A41: Broodmother Lysrix | B41: Gamma | C41: Broodmother Gamma | D41: The Island | E41: 324000 | F41: 0 | G41: 0 | H41: 150 | I41: 0 | J41: 0 | K41: 0 | L41: 0 | M41: 0 | N41: 1500 | O41: 0 | P41: 0 | Q41: 4000 | R41: 0 | S41: 0 | T41: 180 | U41: 0 | V41: 0 | W41: 100 | X41: 0 | Y41: 100000 | Z41: 0
A42: Broodmother Lysrix | B42: Gamma | C42: The Center Gamma | D42: The Center | E42: 356400 | F42: 0 | G42: 0 | H42: 150 | I42: 0 | J42: 0 | K42: 0 | L42: 0 | M42: 0 | N42: 1500 | O42: 0 | P42: 0 | Q42: 4000 | R42: 0 | S42: 0 | T42: 210 | U42: 0 | V42: 0 | W42: 100 | X42: 0 | Y42: 100000 | Z42: 0
A43: Broodmother Lysrix | B43: Beta | C43: The Center Beta | D43: The Center | E43: 421200 | F43: 0 | G43: 0 | H43: 150 | I43: 0 | J43: 0 | K43: 0 | L43: 0 | M43: 0 | N43: 1500 | O43: 0 | P43: 0 | Q43: 4000 | R43: 0 | S43: 0 | T43: 280 | U43: 0 | V43: 0 | W43: 100 | X43: 0 | Y43: 100000 | Z43: 0
...

Sheet Tabelle1
B1: Power | C1: Chance
A2: basic | B2: 1000 | C2: 0.97 | D2: 50 | E2: 0.55
A3: simple | B3: 2000 | C3: 0.97 | D3: 120 | E3: 0.7
A4: regular | B4: 3000 | C4: 0.97 | D4: 300 | E4: 0.8
A5: superior | B5: 4000 | C5: 0.97 | D5: 800 | E5: 0.88
A6: exceptional | B6: 5000 | C6: 0.97 | D6: 2000 | E6: 0.93
A7: extraordinary | B7: 6000 | C7: 0.97 | D7: 5000 | E7: 0.97
E10: Basic Chance 100% | H10: Simple Chance 100% | K10: Regular Chance 100% | N10: Superior Chance 100% | Q10: Exceptional Chance 100% | T10: Extraordinary Chance 100%
B11: 1 | C11: 50 | D11: 150 | E11: 1 | F11: 50 | G11: 150 | H11: 1 | I11: 50 | J11: 150 | K11: 1 | L11: 50 | M11: 150 | N11: 1 | O11: 50 | P11: 150 | Q11: 1 | R11: 50 | S11: 150 | T11: 1 | U11: 50 | V11: 150
A12: =Tabelle2!A3 -> Achatina | B12: =Tabelle2!$N3+(B$11*Tabelle2!$O3) -> 495 | C12: =Tabelle2!$N3+(C$11*Tabelle2!$O3) -> 2700 | D12: =Tabelle2!$N3+(D$11*Tabelle2!$O3) -> 7200 | E12: =POWER($C$2,$B12/$B$2) -> 0.98503579 | F12: =POWER($C$2,$C12/$B$2) -> 0.92105101 | G12: =POWER($C$2,$D12/$B$2) -> 0.8030757 | H12: =POWER($C$3,$B12/$B$3) -> 0.99248969 | I12: =POWER($C$3,$C12/$B$3) -> 0.95971402 | J12: =POWER($C$3,$D12/$B$3) -> 0.89614491 | K12: =POWER($C$4,$B12/$B$4) -> 0.99498684 | L12: =POWER($C$4,$C12/$B$4) -> 0.97295905 | M12: =POWER($C$4,$D12/$B$4) -> 0.92950592 | N12: =POWER($C$5,$B12/$B$5) -> 0.99623777 | O12: =POWER($C$5,$C12/$B$5) -> 0.97964995 | P12: =POWER($C$5,$D12/$B$5) -> 0.94664931 | Q12: =POWER($C$6,$B12/$B$6) -> 0.99698908 | R12: =POWER($C$6,$C12/$B$6) -> 0.98368656 | S12: =POWER($C$6,$D12/$B$6) -> 0.95708674 | T12: =POWER($C$7,$B12/$B$7) -> 0.99749027 | U12: =POWER($C$7,$C12/$B$7) -> 0.98638686 | V12: =POWER($C$7,$D12/$B$7) -> 0.96410888
A13: =Tabelle2!A4 -> Allosaurus | B13: =Tabelle2!$N4+(B$11*Tabelle2!$O4) -> 3300 | C13: =Tabelle2!$N4+(C$11*Tabelle2!$O4) -> 18000 | D13: =Tabelle2!$N4+(D$11*Tabelle2!$O4) -> 48000 | E13: =POWER($C$2,$B13/$B$2) -> 0.9043712 | F13: =POWER($C$2,$C13/$B$2) -> 0.57795126 | G13: =POWER($C$2,$D13/$B$2) -> 0.23176254 | H13: =POWER($C$3,$B13/$B$3) -> 0.95098433 | I13: =POWER($C$3,$C13/$B$3) -> 0.76023106 | J13: =POWER($C$3,$D13/$B$3) -> 0.48141722 | K13: =POWER($C$4,$B13/$B$4) -> 0.96704995 | L13: =POWER($C$4,$C13/$B$4) -> 0.832972 | M13: =POWER($C$4,$D13/$B$4) -> 0.61425365 | N13: =POWER($C$5,$B13/$B$5) -> 0.97518426 | O13: =POWER($C$5,$C13/$B$5) -> 0.8719123 | P13: =POWER($C$5,$D13/$B$5) -> 0.69384236 | Q13: =POWER($C$6,$B13/$B$6) -> 0.98009764 | R13: =POWER($C$6,$C13/$B$6) -> 0.89614491 | S13: =POWER($C$6,$D13/$B$6) -> 0.74646362 | T13: =POWER($C$7,$B13/$B$7) -> 0.98338698 | U13: =POWER($C$7,$C13/$B$7) -> 0.912673 | V13: =POWER($C$7,$D13/$B$7) -> 0.78374336
A14: =Tabelle2!A5 -> Amargasaurus | B14: =Tabelle2!$N5+(B$11*Tabelle2!$O5) -> 6930 | C14: =Tabelle2!$N5+(C$11*Tabelle2!$O5) -> 37800 | D14: =Tabelle2!$N5+(D$11*Tabelle2!$O5) -> 100800 | E14: =POWER($C$2,$B14/$B$2) -> 0.80970742 | F14: =POWER($C$2,$C14/$B$2) -> 0.31620705 | G14: =POWER($C$2,$D14/$B$2) -> 0.046407782 | H14: =POWER($C$3,$B14/$B$3) -> 0.89983744 | I14: =POWER($C$3,$C14/$B$3) -> 0.56232291 | J14: =POWER($C$3,$D14/$B$3) -> 0.21542466 | K14: =POWER($C$4,$B14/$B$4) -> 0.9320575 | L14: =POWER($C$4,$C14/$B$4) -> 0.6812772 | M14: =POWER($C$4,$D14/$B$4) -> 0.35936044 | N14: =POWER($C$5,$B14/$B$5) -> 0.94859762 | O14: =POWER($C$5,$C14/$B$5) -> 0.74988193 | P14: =POWER($C$5,$D14/$B$5) -> 0.46413862 | Q14: =POWER($C$6,$B14/$B$6) -> 0.95866224 | R14: =POWER($C$6,$C14/$B$6) -> 0.79431783 | S14: =POWER($C$6,$D14/$B$6) -> 0.54115062 | T14: =POWER($C$7,$B14/$B$7) -> 0.96543125 | U14: =POWER($C$7,$C14/$B$7) -> 0.82539518 | V14: =POWER($C$7,$D14/$B$7) -> 0.5994668
A15: =Tabelle2!A6 -> Ammonite | B15: =Tabelle2!$N6+(B$11*Tabelle2!$O6) -> 495 | C15: =Tabelle2!$N6+(C$11*Tabelle2!$O6) -> 2700 | D15: =Tabelle2!$N6+(D$11*Tabelle2!$O6) -> 7200 | E15: =POWER($C$2,$B15/$B$2) -> 0.98503579 | F15: =POWER($C$2,$C15/$B$2) -> 0.92105101 | G15: =POWER($C$2,$D15/$B$2) -> 0.8030757 | H15: =POWER($C$3,$B15/$B$3) -> 0.99248969 | I15: =POWER($C$3,$C15/$B$3) -> 0.95971402 | J15: =POWER($C$3,$D15/$B$3) -> 0.89614491 | K15: =POWER($C$4,$B15/$B$4) -> 0.99498684 | L15: =POWER($C$4,$C15/$B$4) -> 0.97295905 | M15: =POWER($C$4,$D15/$B$4) -> 0.92950592 | N15: =POWER($C$5,$B15/$B$5) -> 0.99623777 | O15: =POWER($C$5,$C15/$B$5) -> 0.97964995 | P15: =POWER($C$5,$D15/$B$5) -> 0.94664931 | Q15: =POWER($C$6,$B15/$B$6) -> 0.99698908 | R15: =POWER($C$6,$C15/$B$6) -> 0.98368656 | S15: =POWER($C$6,$D15/$B$6) -> 0.95708674 | T15: =POWER($C$7,$B15/$B$7) -> 0.99749027 | U15: =POWER($C$7,$C15/$B$7) -> 0.98638686 | V15: =POWER($C$7,$D15/$B$7) -> 0.96410888
A16: =Tabelle2!A7 -> Andrewsarchus | B16: =Tabelle2!$N7+(B$11*Tabelle2!$O7) -> 2391.4 | C16: =Tabelle2!$N7+(C$11*Tabelle2!$O7) -> 13044 | D16: =Tabelle2!$N7+(D$11*Tabelle2!$O7) -> 34784 | E16: =POWER($C$2,$B16/$B$2) -> 0.92974944 | F16: =POWER($C$2,$C16/$B$2) -> 0.6721257 | G16: =POWER($C$2,$D16/$B$2) -> 0.34663148 | H16: =POWER($C$3,$B16/$B$3) -> 0.96423516 | I16: =POWER($C$3,$C16/$B$3) -> 0.81983273 | J16: =POWER($C$3,$D16/$B$3) -> 0.58875418 | K16: =POWER($C$4,$B16/$B$4) -> 0.97601234 | L16: =POWER($C$4,$C16/$B$4) -> 0.87595844 | M16: =POWER($C$4,$D16/$B$4) -> 0.70246173 | N16: =POWER($C$5,$B16/$B$5) -> 0.98195476 | O16: =POWER($C$5,$C16/$B$5) -> 0.90544615 | P16: =POWER($C$5,$D16/$B$5) -> 0.76730319 | Q16: =POWER($C$6,$B16/$B$6) -> 0.98553757 | R16: =POWER($C$6,$C16/$B$6) -> 0.92361313 | S16: =POWER($C$6,$D16/$B$6) -> 0.80904672 | T16: =POWER($C$7,$B16/$B$7) -> 0.98793337 | U16: =POWER($C$7,$C16/$B$7) -> 0.93592651 | V16: =POWER($C$7,$D16/$B$7) -> 0.8381299
A17: =Tabelle2!A8 -> Anglerfish | B17: =Tabelle2!$N8+(B$11*Tabelle2!$O8) -> 1650 | C17: =Tabelle2!$N8+(C$11*Tabelle2!$O8) -> 9000 | D17: =Tabelle2!$N8+(D$11*Tabelle2!$O8) -> 24000 | E17: =POWER($C$2,$B17/$B$2) -> 0.95098433 | F17: =POWER($C$2,$C17/$B$2) -> 0.76023106 | G17: =POWER($C$2,$D17/$B$2) -> 0.48141722 | H17: =POWER($C$3,$B17/$B$3) -> 0.97518426 | I17: =POWER($C$3,$C17/$B$3) -> 0.8719123 | J17: =POWER($C$3,$D17/$B$3) -> 0.69384236 | K17: =POWER($C$4,$B17/$B$4) -> 0.98338698 | L17: =POWER($C$4,$C17/$B$4) -> 0.912673 | M17: =POWER($C$4,$D17/$B$4) -> 0.78374336 | N17: =POWER($C$5,$B17/$B$5) -> 0.98751418 | O17: =POWER($C$5,$C17/$B$5) -> 0.93376244 | P17: =POWER($C$5,$D17/$B$5) -> 0.832972 | Q17: =POWER($C$6,$B17/$B$6) -> 0.98999881 | R17: =POWER($C$6,$C17/$B$6) -> 0.94664931 | S17: =POWER($C$6,$D17/$B$6) -> 0.86398126 | T17: =POWER($C$7,$B17/$B$7) -> 0.9916587 | U17: =POWER($C$7,$C17/$B$7) -> 0.95533921 | V17: =POWER($C$7,$D17/$B$7) -> 0.88529281
A18: =Tabelle2!A9 -> Ankylosaurus | B18: =Tabelle2!$N9+(B$11*Tabelle2!$O9) -> 3300 | C18: =Tabelle2!$N9+(C$11*Tabelle2!$O9) -> 18000 | D18: =Tabelle2!$N9+(D$11*Tabelle2!$O9) -> 48000 | E18: =POWER($C$2,$B18/$B$2) -> 0.9043712 | F18: =POWER($C$2,$C18/$B$2) -> 0.57795126 | G18: =POWER($C$2,$D18/$B$2) -> 0.23176254 | H18: =POWER($C$3,$B18/$B$3) -> 0.95098433 | I18: =POWER($C$3,$C18/$B$3) -> 0.76023106 | J18: =POWER($C$3,$D18/$B$3) -> 0.48141722 | K18: =POWER($C$4,$B18/$B$4) -> 0.96704995 | L18: =POWER($C$4,$C18/$B$4) -> 0.832972 | M18: =POWER($C$4,$D18/$B$4) -> 0.61425365 | N18: =POWER($C$5,$B18/$B$5) -> 0.97518426 | O18: =POWER($C$5,$C18/$B$5) -> 0.8719123 | P18: =POWER($C$5,$D18/$B$5) -> 0.69384236 | Q18: =POWER($C$6,$B18/$B$6) -> 0.98009764 | R18: =POWER($C$6,$C18/$B$6) -> 0.89614491 | S18: =POWER($C$6,$D18/$B$6) -> 0.74646362 | T18: =POWER($C$7,$B18/$B$7) -> 0.98338698 | U18: =POWER($C$7,$C18/$B$7) -> 0.912673 | V18: =POWER($C$7,$D18/$B$7) -> 0.78374336
A19: =Tabelle2!A10 -> Araneo | B19: =Tabelle2!$N10+(B$11*Tabelle2!$O10) -> 990 | C19: =Tabelle2!$N10+(C$11*Tabelle2!$O10) -> 5400 | D19: =Tabelle2!$N10+(D$11*Tabelle2!$O10) -> 14400 | E19: =POWER($C$2,$B19/$B$2) -> 0.9702955 | F19: =POWER($C$2,$C19/$B$2) -> 0.84833496 | G19: =POWER($C$2,$D19/$B$2) -> 0.64493059 | H19: =POWER($C$3,$B19/$B$3) -> 0.98503579 | I19: =POWER($C$3,$C19/$B$3) -> 0.92105101 | J19: =POWER($C$3,$D19/$B$3) -> 0.8030757 | K19: =POWER($C$4,$B19/$B$4) -> 0.98999881 | L19: =POWER($C$4,$C19/$B$4) -> 0.94664931 | M19: =POWER($C$4,$D19/$B$4) -> 0.86398126 | N19: =POWER($C$5,$B19/$B$5) -> 0.99248969 | O19: =POWER($C$5,$C19/$B$5) -> 0.95971402 | P19: =POWER($C$5,$D19/$B$5) -> 0.89614491 | Q19: =POWER($C$6,$B19/$B$6) -> 0.99398723 | R19: =POWER($C$6,$C19/$B$6) -> 0.96763924 | S19: =POWER($C$6,$D19/$B$6) -> 0.91601502 | T19: =POWER($C$7,$B19/$B$7) -> 0.99498684 | U19: =POWER($C$7,$C19/$B$7) -> 0.97295905 | V19: =POWER($C$7,$D19/$B$7) -> 0.92950592
A20: =Tabelle2!A11 -> Archaeopteryx | B20: =Tabelle2!$N11+(B$11*Tabelle2!$O11) -> 990 | C20: =Tabelle2!$N11+(C$11*Tabelle2!$O11) -> 5400 | D20: =Tabelle2!$N11+(D$11*Tabelle2!$O11) -> 14400 | E20: =POWER($C$2,$B20/$B$2) -> 0.9702955 | F20: =POWER($C$2,$C20/$B$2) -> 0.84833496 | G20: =POWER($C$2,$D20/$B$2) -> 0.64493059 | H20: =POWER($C$3,$B20/$B$3) -> 0.98503579 | I20: =POWER($C$3,$C20/$B$3) -> 0.92105101 | J20: =POWER($C$3,$D20/$B$3) -> 0.8030757 | K20: =POWER($C$4,$B20/$B$4) -> 0.98999881 | L20: =POWER($C$4,$C20/$B$4) -> 0.94664931 | M20: =POWER($C$4,$D20/$B$4) -> 0.86398126 | N20: =POWER($C$5,$B20/$B$5) -> 0.99248969 | O20: =POWER($C$5,$C20/$B$5) -> 0.95971402 | P20: =POWER($C$5,$D20/$B$5) -> 0.89614491 | Q20: =POWER($C$6,$B20/$B$6) -> 0.99398723 | R20: =POWER($C$6,$C20/$B$6) -> 0.96763924 | S20: =POWER($C$6,$D20/$B$6) -> 0.91601502 | T20: =POWER($C$7,$B20/$B$7) -> 0.99498684 | U20: =POWER($C$7,$C20/$B$7) -> 0.97295905 | V20: =POWER($C$7,$D20/$B$7) -> 0.92950592
A21: =Tabelle2!A12 -> Archelon | B21: =Tabelle2!$N12+(B$11*Tabelle2!$O12) -> 3850 | C21: =Tabelle2!$N12+(C$11*Tabelle2!$O12) -> 21000 | D21: =Tabelle2!$N12+(D$11*Tabelle2!$O12) -> 56000 | E21: =POWER($C$2,$B21/$B$2) -> 0.88934686 | F21: =POWER($C$2,$C21/$B$2) -> 0.52748051 | G21: =POWER($C$2,$D21/$B$2) -> 0.18164235 | H21: =POWER($C$3,$B21/$B$3) -> 0.94305189 | I21: =POWER($C$3,$C21/$B$3) -> 0.72627854 | J21: =POWER($C$3,$D21/$B$3) -> 0.42619521 | K21: =POWER($C$4,$B21/$B$4) -> 0.96166481 | L21: =POWER($C$4,$C21/$B$4) -> 0.80798284 | M21: =POWER($C$4,$D21/$B$4) -> 0.56633366 | N21: =POWER($C$5,$B21/$B$5) -> 0.97110859 | O21: =POWER($C$5,$C21/$B$5) -> 0.85221977 | P21: =POWER($C$5,$D21/$B$5) -> 0.65283628 | Q21: =POWER($C$6,$B21/$B$6) -> 0.97681931 | R21: =POWER($C$6,$C21/$B$6) -> 0.87991614 | S21: =POWER($C$6,$D21/$B$6) -> 0.71095715 | T21: =POWER($C$7,$B21/$B$7) -> 0.9806451 | U21: =POWER($C$7,$C21/$B$7) -> 0.89887866 | V21: =POWER($C$7,$D21/$B$7) -> 0.75255143
A22: =Tabelle2!A13 -> Argentavis | B22: =Tabelle2!$N13+(B$11*Tabelle2!$O13) -> 2200 | C22: =Tabelle2!$N13+(C$11*Tabelle2!$O13) -> 12000 | D22: =Tabelle2!$N13+(D$11*Tabelle2!$O13) -> 32000 | E22: =POWER($C$2,$B22/$B$2) -> 0.93518561 | F22: =POWER($C$2,$C22/$B$2) -> 0.69384236 | G22: =POWER($C$2,$D22/$B$2) -> 0.37730755 | H22: =POWER($C$3,$B22/$B$3) -> 0.96704995 | I22: =POWER($C$3,$C22/$B$3) -> 0.832972 | J22: =POWER($C$3,$D22/$B$3) -> 0.61425365 | K22: =POWER($C$4,$B22/$B$4) -> 0.97791087 | L22: =POWER($C$4,$C22/$B$4) -> 0.88529281 | M22: =POWER($C$4,$D22/$B$4) -> 0.7226009 | N22: =POWER($C$5,$B22/$B$5) -> 0.98338698 | O22: =POWER($C$5,$C22/$B$5) -> 0.912673 | P22: =POWER($C$5,$D22/$B$5) -> 0.78374336 | Q22: =POWER($C$6,$B22/$B$6) -> 0.98668736 | R22: =POWER($C$6,$C22/$B$6) -> 0.92950592 | S22: =POWER($C$6,$D22/$B$6) -> 0.82288491 | T22: =POWER($C$7,$B22/$B$7) -> 0.98889376 | U22: =POWER($C$7,$C22/$B$7) -> 0.9409 | V22: =POWER($C$7,$D22/$B$7) -> 0.85005935
A23: =Tabelle2!A14 -> Armadoggo | B23: =Tabelle2!$N14+(B$11*Tabelle2!$O14) -> 1320 | C23: =Tabelle2!$N14+(C$11*Tabelle2!$O14) -> 7200 | D23: =Tabelle2!$N14+(D$11*Tabelle2!$O14) -> 19200 | E23: =POWER($C$2,$B23/$B$2) -> 0.96059139 | F23: =POWER($C$2,$C23/$B$2) -> 0.8030757 | G23: =POWER($C$2,$D23/$B$2) -> 0.55720794 | H23: =POWER($C$3,$B23/$B$3) -> 0.98009764 | I23: =POWER($C$3,$C23/$B$3) -> 0.89614491 | J23: =POWER($C$3,$D23/$B$3) -> 0.74646362 | K23: =POWER($C$4,$B23/$B$4) -> 0.98668736 | L23: =POWER($C$4,$C23/$B$4) -> 0.92950592 | M23: =POWER($C$4,$D23/$B$4) -> 0.82288491 | N23: =POWER($C$5,$B23/$B$5) -> 0.98999881 | O23: =POWER($C$5,$C23/$B$5) -> 0.94664931 | P23: =POWER($C$5,$D23/$B$5) -> 0.86398126 | Q23: =POWER($C$6,$B23/$B$6) -> 0.99199101 | R23: =POWER($C$6,$C23/$B$6) -> 0.95708674 | S23: =POWER($C$6,$D23/$B$6) -> 0.88961779 | T23: =POWER($C$7,$B23/$B$7) -> 0.99332138 | U23: =POWER($C$7,$C23/$B$7) -> 0.96410888 | V23: =POWER($C$7,$D23/$B$7) -> 0.90713004
... A29: =Tabelle2!A20 -> Attack Drone | B29: =Tabelle2!$N20+(B$11*Tabelle2!$O20) -> 1600 | C29: =Tabelle2!$N20+(C$11*Tabelle2!$O20) -> 1600 | D29: =Tabelle2!$N20+(D$11*Tabelle2!$O20) -> 1600 | E29: =POWER($C$2,$B29/$B$2) -> 0.95243375 | F29: =POWER($C$2,$C29/$B$2) -> 0.95243375 | G29: =POWER($C$2,$D29/$B$2) -> 0.95243375 | H29: =POWER($C$3,$B29/$B$3) -> 0.97592712 | I29: =POWER($C$3,$C29/$B$3) -> 0.97592712 | J29: =POWER($C$3,$D29/$B$3) -> 0.97592712 | K29: =POWER($C$4,$B29/$B$4) -> 0.98388633 | L29: =POWER($C$4,$C29/$B$4) -> 0.98388633 | M29: =POWER($C$4,$D29/$B$4) -> 0.98388633 | N29: =POWER($C$5,$B29/$B$5) -> 0.98789024 | O29: =POWER($C$5,$C29/$B$5) -> 0.98789024 | P29: =POWER($C$5,$D29/$B$5) -> 0.98789024 | Q29: =POWER($C$6,$B29/$B$6) -> 0.9903004 | R29: =POWER($C$6,$C29/$B$6) -> 0.9903004 | S29: =POWER($C$6,$D29/$B$6) -> 0.9903004 | T29: =POWER($C$7,$B29/$B$7) -> 0.99191044 | U29: =POWER($C$7,$C29/$B$7) -> 0.99191044 | V29: =POWER($C$7,$D29/$B$7) -> 0.99191044
A30: =Tabelle2!A33 -> Baryonyx | B30: =Tabelle2!$N33+(B$11*Tabelle2!$O33) -> 2475 | C30: =Tabelle2!$N33+(C$11*Tabelle2!$O33) -> 13500 | D30: =Tabelle2!$N33+(D$11*Tabelle2!$O33) -> 36000 | E30: =POWER($C$2,$B30/$B$2) -> 0.92738495 | F30: =POWER($C$2,$C30/$B$2) -> 0.66285481 | G30: =POWER($C$2,$D30/$B$2) -> 0.33402766 | H30: =POWER($C$3,$B30/$B$3) -> 0.96300828 | I30: =POWER($C$3,$C30/$B$3) -> 0.81415896 | J30: =POWER($C$3,$D30/$B$3) -> 0.57795126 | K30: =POWER($C$4,$B30/$B$4) -> 0.97518426 | L30: =POWER($C$4,$C30/$B$4) -> 0.8719123 | M30: =POWER($C$4,$D30/$B$4) -> 0.69384236 | N30: =POWER($C$5,$B30/$B$5) -> 0.98132985 | O30: =POWER($C$5,$C30/$B$5) -> 0.90230757 | P30: =POWER($C$5,$D30/$B$5) -> 0.76023106 | Q30: =POWER($C$6,$B30/$B$6) -> 0.98503579 | R30: =POWER($C$6,$C30/$B$6) -> 0.92105101 | S30: =POWER($C$6,$D30/$B$6) -> 0.8030757 | T30: =POWER($C$7,$B30/$B$7) -> 0.98751418 | U30: =POWER($C$7,$C30/$B$7) -> 0.93376244 | V30: =POWER($C$7,$D30/$B$7) -> 0.832972
A31: =Tabelle2!A34 -> Basilisk | B31: =Tabelle2!$N34+(B$11*Tabelle2!$O34) -> 2750 | C31: =Tabelle2!$N34+(C$11*Tabelle2!$O34) -> 15000 | D31: =Tabelle2!$N34+(D$11*Tabelle2!$O34) -> 40000 | E31: =POWER($C$2,$B31/$B$2) -> 0.91964935 | F31: =POWER($C$2,$C31/$B$2) -> 0.63325119 | G31: =POWER($C$2,$D31/$B$2) -> 0.29571229 | H31: =POWER($C$3,$B31/$B$3) -> 0.9589835 | I31: =POWER($C$3,$C31/$B$3) -> 0.79577081 | J31: =POWER($C$3,$D31/$B$3) -> 0.54379434 | K31: =POWER($C$4,$B31/$B$4) -> 0.97246525 | L31: =POWER($C$4,$C31/$B$4) -> 0.85873403 | M31: =POWER($C$4,$D31/$B$4) -> 0.66622837 | N31: =POWER($C$5,$B31/$B$5) -> 0.97927703 | O31: =POWER($C$5,$C31/$B$5) -> 0.89205987 | P31: =POWER($C$5,$D31/$B$5) -> 0.73742413 | Q31: =POWER($C$6,$B31/$B$6) -> 0.98338698 | R31: =POWER($C$6,$C31/$B$6) -> 0.912673 | S31: =POWER($C$6,$D31/$B$6) -> 0.78374336 | T31: =POWER($C$7,$B31/$B$7) -> 0.98613653 | U31: =POWER($C$7,$C31/$B$7) -> 0.92667903 | V31: =POWER($C$7,$D31/$B$7) -> 0.81622814
A32: =Tabelle2!A35 -> Basilosaurus | B32: =Tabelle2!$N35+(B$11*Tabelle2!$O35) -> 8800 | C32: =Tabelle2!$N35+(C$11*Tabelle2!$O35) -> 48000 | D32: =Tabelle2!$N35+(D$11*Tabelle2!$O35) -> 128000 | E32: =POWER($C$2,$B32/$B$2) -> 0.7648764 | F32: =POWER($C$2,$C32/$B$2) -> 0.23176254 | G32: =POWER($C$2,$D32/$B$2) -> 0.020266651 | H32: =POWER($C$3,$B32/$B$3) -> 0.87457212 | I32: =POWER($C$3,$C32/$B$3) -> 0.48141722 | J32: =POWER($C$3,$D32/$B$3) -> 0.14236099 | K32: =POWER($C$4,$B32/$B$4) -> 0.91452817 | L32: =POWER($C$4,$C32/$B$4) -> 0.61425365 | M32: =POWER($C$4,$D32/$B$4) -> 0.27264278 | N32: =POWER($C$5,$B32/$B$5) -> 0.93518561 | O32: =POWER($C$5,$C32/$B$5) -> 0.69384236 | P32: =POWER($C$5,$D32/$B$5) -> 0.37730755 | Q32: =POWER($C$6,$B32/$B$6) -> 0.94780338 | R32: =POWER($C$6,$C32/$B$6) -> 0.74646362 | S32: =POWER($C$6,$D32/$B$6) -> 0.45851801 | T32: =POWER($C$7,$B32/$B$7) -> 0.95630966 | U32: =POWER($C$7,$C32/$B$7) -> 0.78374336 | V32: =POWER($C$7,$D32/$B$7) -> 0.52215206
A33: =Tabelle2!A36 -> Beelzebufo | B33: =Tabelle2!$N36+(B$11*Tabelle2!$O36) -> 1650 | C33: =Tabelle2!$N36+(C$11*Tabelle2!$O36) -> 9000 | D33: =Tabelle2!$N36+(D$11*Tabelle2!$O36) -> 24000 | E33: =POWER($C$2,$B33/$B$2) -> 0.95098433 | F33: =POWER($C$2,$C33/$B$2) -> 0.76023106 | G33: =POWER($C$2,$D33/$B$2) -> 0.48141722 | H33: =POWER($C$3,$B33/$B$3) -> 0.97518426 | I33: =POWER($C$3,$C33/$B$3) -> 0.8719123 | J33: =POWER($C$3,$D33/$B$3) -> 0.69384236 | K33: =POWER($C$4,$B33/$B$4) -> 0.98338698 | L33: =POWER($C$4,$C33/$B$4) -> 0.912673 | M33: =POWER($C$4,$D33/$B$4) -> 0.78374336 | N33: =POWER($C$5,$B33/$B$5) -> 0.98751418 | O33: =POWER($C$5,$C33/$B$5) -> 0.93376244 | P33: =POWER($C$5,$D33/$B$5) -> 0.832972 | Q33: =POWER($C$6,$B33/$B$6) -> 0.98999881 | R33: =POWER($C$6,$C33/$B$6) -> 0.94664931 | S33: =POWER($C$6,$D33/$B$6) -> 0.86398126 | T33: =POWER($C$7,$B33/$B$7) -> 0.9916587 | U33: =POWER($C$7,$C33/$B$7) -> 0.95533921 | V33: =POWER($C$7,$D33/$B$7) -> 0.88529281
A34: =Tabelle2!A37 -> Beyla | B34: =Tabelle2!$N37+(B$11*Tabelle2!$O37) -> 1500 | C34: =Tabelle2!$N37+(C$11*Tabelle2!$O37) -> 1500 | D34: =Tabelle2!$N37+(D$11*Tabelle2!$O37) -> 1500 | E34: =POWER($C$2,$B34/$B$2) -> 0.95533921 | F34: =POWER($C$2,$C34/$B$2) -> 0.95533921 | G34: =POWER($C$2,$D34/$B$2) -> 0.95533921 | H34: =POWER($C$3,$B34/$B$3) -> 0.97741455 | I34: =POWER($C$3,$C34/$B$3) -> 0.97741455 | J34: =POWER($C$3,$D34/$B$3) -> 0.97741455 | K34: =POWER($C$4,$B34/$B$4) -> 0.98488578 | L34: =POWER($C$4,$C34/$B$4) -> 0.98488578 | M34: =POWER($C$4,$D34/$B$4) -> 0.98488578 | N34: =POWER($C$5,$B34/$B$5) -> 0.98864278 | O34: =POWER($C$5,$C34/$B$5) -> 0.98864278 | P34: =POWER($C$5,$D34/$B$5) -> 0.98864278 | Q34: =POWER($C$6,$B34/$B$6) -> 0.99090386 | R34: =POWER($C$6,$C34/$B$6) -> 0.99090386 | S34: =POWER($C$6,$D34/$B$6) -> 0.99090386 | T34: =POWER($C$7,$B34/$B$7) -> 0.99241412 | U34: =POWER($C$7,$C34/$B$7) -> 0.99241412 | V34: =POWER($C$7,$D34/$B$7) -> 0.99241412
A35: =Tabelle2!A38 -> Bison | B35: =Tabelle2!$N38+(B$11*Tabelle2!$O38) -> 3575 | C35: =Tabelle2!$N38+(C$11*Tabelle2!$O38) -> 19500 | D35: =Tabelle2!$N38+(D$11*Tabelle2!$O38) -> 52000 | E35: =POWER($C$2,$B35/$B$2) -> 0.89682757 | F35: =POWER($C$2,$C35/$B$2) -> 0.5521395 | G35: =POWER($C$2,$D35/$B$2) -> 0.20517771 | H35: =POWER($C$3,$B35/$B$3) -> 0.9470098 | I35: =POWER($C$3,$C35/$B$3) -> 0.7430609 | J35: =POWER($C$3,$D35/$B$3) -> 0.45296546 | K35: =POWER($C$4,$B35/$B$4) -> 0.96435362 | L35: =POWER($C$4,$C35/$B$4) -> 0.82038228 | M35: =POWER($C$4,$D35/$B$4) -> 0.58980719 | N35: =POWER($C$5,$B35/$B$5) -> 0.97314429 | O35: =POWER($C$5,$C35/$B$5) -> 0.8620098 | P35: =POWER($C$5,$D35/$B$5) -> 0.67302709 | Q35: =POWER($C$6,$B35/$B$6) -> 0.9784571 | R35: =POWER($C$6,$C35/$B$6) -> 0.88799345 | S35: =POWER($C$6,$D35/$B$6) -> 0.7284941 | T35: =POWER($C$7,$B35/$B$7) -> 0.98201508 | U35: =POWER($C$7,$C35/$B$7) -> 0.90574957 | V35: =POWER($C$7,$D35/$B$7) -> 0.76798905
A36: =Tabelle2!A39 -> Bloodstalker | B36: =Tabelle2!$N39+(B$11*Tabelle2!$O39) -> 1320 | C36: =Tabelle2!$N39+(C$11*Tabelle2!$O39) -> 7200 | D36: =Tabelle2!$N39+(D$11*Tabelle2!$O39) -> 19200 | E36: =POWER($C$2,$B36/$B$2) -> 0.96059139 | F36: =POWER($C$2,$C36/$B$2) -> 0.8030757 | G36: =POWER($C$2,$D36/$B$2) -> 0.55720794 | H36: =POWER($C$3,$B36/$B$3) -> 0.98009764 | I36: =POWER($C$3,$C36/$B$3) -> 0.89614491 | J36: =POWER($C$3,$D36/$B$3) -> 0.74646362 | K36: =POWER($C$4,$B36/$B$4) -> 0.98668736 | L36: =POWER($C$4,$C36/$B$4) -> 0.92950592 | M36: =POWER($C$4,$D36/$B$4) -> 0.82288491 | N36: =POWER($C$5,$B36/$B$5) -> 0.98999881 | O36: =POWER($C$5,$C36/$B$5) -> 0.94664931 | P36: =POWER($C$5,$D36/$B$5) -> 0.86398126 | Q36: =POWER($C$6,$B36/$B$6) -> 0.99199101 | R36: =POWER($C$6,$C36/$B$6) -> 0.95708674 | S36: =POWER($C$6,$D36/$B$6) -> 0.88961779 | T36: =POWER($C$7,$B36/$B$7) -> 0.99332138 | U36: =POWER($C$7,$C36/$B$7) -> 0.96410888 | V36: =POWER($C$7,$D36/$B$7) -> 0.90713004
A37: =Tabelle2!A40 -> Brontosaurus | B37: =Tabelle2!$N40+(B$11*Tabelle2!$O40) -> 11000 | C37: =Tabelle2!$N40+(C$11*Tabelle2!$O40) -> 60000 | D37: =Tabelle2!$N40+(D$11*Tabelle2!$O40) -> 160000 | E37: =POWER($C$2,$B37/$B$2) -> 0.7153014 | F37: =POWER($C$2,$C37/$B$2) -> 0.16080667 | G37: =POWER($C$2,$D37/$B$2) -> 0.0076467604 | H37: =POWER($C$3,$B37/$B$3) -> 0.84575493 | I37: =POWER($C$3,$C37/$B$3) -> 0.40100707 | J37: =POWER($C$3,$D37/$B$3) -> 0.087445757 | K37: =POWER($C$4,$B37/$B$4) -> 0.89432703 | L37: =POWER($C$4,$C37/$B$4) -> 0.54379434 | M37: =POWER($C$4,$D37/$B$4) -> 0.19701192 | N37: =POWER($C$5,$B37/$B$5) -> 0.91964935 | O37: =POWER($C$5,$C37/$B$5) -> 0.63325119 | P37: =POWER($C$5,$D37/$B$5) -> 0.29571229 | Q37: =POWER($C$6,$B37/$B$6) -> 0.93518561 | R37: =POWER($C$6,$C37/$B$6) -> 0.69384236 | S37: =POWER($C$6,$D37/$B$6) -> 0.37730755 | T37: =POWER($C$7,$B37/$B$7) -> 0.94568866 | U37: =POWER($C$7,$C37/$B$7) -> 0.73742413 | V37: =POWER($C$7,$D37/$B$7) -> 0.44386024
A38: =Tabelle2!A41 -> Broodmother Lysrix | B38: =Tabelle2!$N41+(B$11*Tabelle2!$O41) -> 1500 | C38: =Tabelle2!$N41+(C$11*Tabelle2!$O41) -> 1500 | D38: =Tabelle2!$N41+(D$11*Tabelle2!$O41) -> 1500 | E38: =POWER($C$2,$B38/$B$2) -> 0.95533921 | F38: =POWER($C$2,$C38/$B$2) -> 0.95533921 | G38: =POWER($C$2,$D38/$B$2) -> 0.95533921 | H38: =POWER($C$3,$B38/$B$3) -> 0.97741455 | I38: =POWER($C$3,$C38/$B$3) -> 0.97741455 | J38: =POWER($C$3,$D38/$B$3) -> 0.97741455 | K38: =POWER($C$4,$B38/$B$4) -> 0.98488578 | L38: =POWER($C$4,$C38/$B$4) -> 0.98488578 | M38: =POWER($C$4,$D38/$B$4) -> 0.98488578 | N38: =POWER($C$5,$B38/$B$5) -> 0.98864278 | O38: =POWER($C$5,$C38/$B$5) -> 0.98864278 | P38: =POWER($C$5,$D38/$B$5) -> 0.98864278 | Q38: =POWER($C$6,$B38/$B$6) -> 0.99090386 | R38: =POWER($C$6,$C38/$B$6) -> 0.99090386 | S38: =POWER($C$6,$D38/$B$6) -> 0.99090386 | T38: =POWER($C$7,$B38/$B$7) -> 0.99241412 | U38: =POWER($C$7,$C38/$B$7) -> 0.99241412 | V38: =POWER($C$7,$D38/$B$7) -> 0.99241412
A39: =Tabelle2!A42 -> Broodmother Lysrix | B39: =Tabelle2!$N42+(B$11*Tabelle2!$O42) -> 1500 | C39: =Tabelle2!$N42+(C$11*Tabelle2!$O42) -> 1500 | D39: =Tabelle2!$N42+(D$11*Tabelle2!$O42) -> 1500 | E39: =POWER($C$2,$B39/$B$2) -> 0.95533921 | F39: =POWER($C$2,$C39/$B$2) -> 0.95533921 | G39: =POWER($C$2,$D39/$B$2) -> 0.95533921 | H39: =POWER($C$3,$B39/$B$3) -> 0.97741455 | I39: =POWER($C$3,$C39/$B$3) -> 0.97741455 | J39: =POWER($C$3,$D39/$B$3) -> 0.97741455 | K39: =POWER($C$4,$B39/$B$4) -> 0.98488578 | L39: =POWER($C$4,$C39/$B$4) -> 0.98488578 | M39: =POWER($C$4,$D39/$B$4) -> 0.98488578 | N39: =POWER($C$5,$B39/$B$5) -> 0.98864278 | O39: =POWER($C$5,$C39/$B$5) -> 0.98864278 | P39: =POWER($C$5,$D39/$B$5) -> 0.98864278 | Q39: =POWER($C$6,$B39/$B$6) -> 0.99090386 | R39: =POWER($C$6,$C39/$B$6) -> 0.99090386 | S39: =POWER($C$6,$D39/$B$6) -> 0.99090386 | T39: =POWER($C$7,$B39/$B$7) -> 0.99241412 | U39: =POWER($C$7,$C39/$B$7) -> 0.99241412 | V39: =POWER($C$7,$D39/$B$7) -> 0.99241412
A40: =Tabelle2!A43 -> Broodmother Lysrix | B40: =Tabelle2!$N43+(B$11*Tabelle2!$O43) -> 1500 | C40: =Tabelle2!$N43+(C$11*Tabelle2!$O43) -> 1500 | D40: =Tabelle2!$N43+(D$11*Tabelle2!$O43) -> 1500 | E40: =POWER($C$2,$B40/$B$2) -> 0.95533921 | F40: =POWER($C$2,$C40/$B$2) -> 0.95533921 | G40: =POWER($C$2,$D40/$B$2) -> 0.95533921 | H40: =POWER($C$3,$B40/$B$3) -> 0.97741455 | I40: =POWER($C$3,$C40/$B$3) -> 0.97741455 | J40: =POWER($C$3,$D40/$B$3) -> 0.97741455 | K40: =POWER($C$4,$B40/$B$4) -> 0.98488578 | L40: =POWER($C$4,$C40/$B$4) -> 0.98488578 | M40: =POWER($C$4,$D40/$B$4) -> 0.98488578 | N40: =POWER($C$5,$B40/$B$5) -> 0.98864278 | O40: =POWER($C$5,$C40/$B$5) -> 0.98864278 | P40: =POWER($C$5,$D40/$B$5) -> 0.98864278 | Q40: =POWER($C$6,$B40/$B$6) -> 0.99090386 | R40: =POWER($C$6,$C40/$B$6) -> 0.99090386 | S40: =POWER($C$6,$D40/$B$6) -> 0.99090386 | T40: =POWER($C$7,$B40/$B$7) -> 0.99241412 | U40: =POWER($C$7,$C40/$B$7) -> 0.99241412 | V40: =POWER($C$7,$D40/$B$7) -> 0.99241412
A41: =Tabelle2!A44 -> Broodmother Lysrix | B41: =Tabelle2!$N44+(B$11*Tabelle2!$O44) -> 1500 | C41: =Tabelle2!$N44+(C$11*Tabelle2!$O44) -> 1500 | D41: =Tabelle2!$N44+(D$11*Tabelle2!$O44) -> 1500 | E41: =POWER($C$2,$B41/$B$2) -> 0.95533921 | F41: =POWER($C$2,$C41/$B$2) -> 0.95533921 | G41: =POWER($C$2,$D41/$B$2) -> 0.95533921 | H41: =POWER($C$3,$B41/$B$3) -> 0.97741455 | I41: =POWER($C$3,$C41/$B$3) -> 0.97741455 | J41: =POWER($C$3,$D41/$B$3) -> 0.97741455 | K41: =POWER($C$4,$B41/$B$4) -> 0.98488578 | L41: =POWER($C$4,$C41/$B$4) -> 0.98488578 | M41: =POWER($C$4,$D41/$B$4) -> 0.98488578 | N41: =POWER($C$5,$B41/$B$5) -> 0.98864278 | O41: =POWER($C$5,$C41/$B$5) -> 0.98864278 | P41: =POWER($C$5,$D41/$B$5) -> 0.98864278 | Q41: =POWER($C$6,$B41/$B$6) -> 0.99090386 | R41: =POWER($C$6,$C41/$B$6) -> 0.99090386 | S41: =POWER($C$6,$D41/$B$6) -> 0.99090386 | T41: =POWER($C$7,$B41/$B$7) -> 0.99241412 | U41: =POWER($C$7,$C41/$B$7) -> 0.99241412 | V41: =POWER($C$7,$D41/$B$7) -> 0.99241412
... A69: =Tabelle2!A72 -> Defense Unit | B69: =Tabelle2!$N72+(B$11*Tabelle2!$O72) -> 3000 | C69: =Tabelle2!$N72+(C$11*Tabelle2!$O72) -> 3000 | D69: =Tabelle2!$N72+(D$11*Tabelle2!$O72) -> 3000 | E69: =POWER($C$2,$B69/$B$2) -> 0.912673 | F69: =POWER($C$2,$C69/$B$2) -> 0.912673 | G69: =POWER($C$2,$D69/$B$2) -> 0.912673 | H69: =POWER($C$3,$B69/$B$3) -> 0.95533921 | I69: =POWER($C$3,$C69/$B$3) -> 0.95533921 | J69: =POWER($C$3,$D69/$B$3) -> 0.95533921 | K69: =POWER($C$4,$B69/$B$4) -> 0.97 | L69: =POWER($C$4,$C69/$B$4) -> 0.97 | M69: =POWER($C$4,$D69/$B$4) -> 0.97 | N69: =POWER($C$5,$B69/$B$5) -> 0.97741455 | O69: =POWER($C$5,$C69/$B$5) -> 0.97741455 | P69: =POWER($C$5,$D69/$B$5) -> 0.97741455 | Q69: =POWER($C$6,$B69/$B$6) -> 0.98189046 | R69: =POWER($C$6,$C69/$B$6) -> 0.98189046 | S69: =POWER($C$6,$D69/$B$6) -> 0.98189046 | T69: =POWER($C$7,$B69/$B$7) -> 0.98488578 | U69: =POWER($C$7,$C69/$B$7) -> 0.98488578 | V69: =POWER($C$7,$D69/$B$7) -> 0.98488578
A70: =Tabelle2!A85 -> Deinonychus | B70: =Tabelle2!$N85+(B$11*Tabelle2!$O85) -> 1320 | C70: =Tabelle2!$N85+(C$11*Tabelle2!$O85) -> 7200 | D70: =Tabelle2!$N85+(D$11*Tabelle2!$O85) -> 19200 | E70: =POWER($C$2,$B70/$B$2) -> 0.96059139 | F70: =POWER($C$2,$C70/$B$2) -> 0.8030757 | G70: =POWER($C$2,$D70/$B$2) -> 0.55720794 | H70: =POWER($C$3,$B70/$B$3) -> 0.98009764 | I70: =POWER($C$3,$C70/$B$3) -> 0.89614491 | J70: =POWER($C$3,$D70/$B$3) -> 0.74646362 | K70: =POWER($C$4,$B70/$B$4) -> 0.98668736 | L70: =POWER($C$4,$C70/$B$4) -> 0.92950592 | M70: =POWER($C$4,$D70/$B$4) -> 0.82288491 | N70: =POWER($C$5,$B70/$B$5) -> 0.98999881 | O70: =POWER($C$5,$C70/$B$5) -> 0.94664931 | P70: =POWER($C$5,$D70/$B$5) -> 0.86398126 | Q70: =POWER($C$6,$B70/$B$6) -> 0.99199101 | R70: =POWER($C$6,$C70/$B$6) -> 0.95708674 | S70: =POWER($C$6,$D70/$B$6) -> 0.88961779 | T70: =POWER($C$7,$B70/$B$7) -> 0.99332138 | U70: =POWER($C$7,$C70/$B$7) -> 0.96410888 | V70: =POWER($C$7,$D70/$B$7) -> 0.90713004
A71: =Tabelle2!A86 -> Desert Titan Flock | B71: =Tabelle2!$N86+(B$11*Tabelle2!$O86) -> 100 | C71: =Tabelle2!$N86+(C$11*Tabelle2!$O86) -> 100 | D71: =Tabelle2!$N86+(D$11*Tabelle2!$O86) -> 100 | E71: =POWER($C$2,$B71/$B$2) -> 0.99695871 | F71: =POWER($C$2,$C71/$B$2) -> 0.99695871 | G71: =POWER($C$2,$D71/$B$2) -> 0.99695871 | H71: =POWER($C$3,$B71/$B$3) -> 0.9984782 | I71: =POWER($C$3,$C71/$B$3) -> 0.9984782 | J71: =POWER($C$3,$D71/$B$3) -> 0.9984782 | K71: =POWER($C$4,$B71/$B$4) -> 0.99898521 | L71: =POWER($C$4,$C71/$B$4) -> 0.99898521 | M71: =POWER($C$4,$D71/$B$4) -> 0.99898521 | N71: =POWER($C$5,$B71/$B$5) -> 0.99923881 | O71: =POWER($C$5,$C71/$B$5) -> 0.99923881 | P71: =POWER($C$5,$D71/$B$5) -> 0.99923881 | Q71: =POWER($C$6,$B71/$B$6) -> 0.999391 | R71: =POWER($C$6,$C71/$B$6) -> 0.999391 | S71: =POWER($C$6,$D71/$B$6) -> 0.999391 | T71: =POWER($C$7,$B71/$B$7) -> 0.99949248 | U71: =POWER($C$7,$C71/$B$7) -> 0.99949248 | V71: =POWER($C$7,$D71/$B$7) -> 0.99949248
A72: =Tabelle2!A88 -> Desert Titan | B72: =Tabelle2!$N88+(B$11*Tabelle2!$O88) -> 864 | C72: =Tabelle2!$N88+(C$11*Tabelle2!$O88) -> 864 | D72: =Tabelle2!$N88+(D$11*Tabelle2!$O88) -> 864 | E72: =POWER($C$2,$B72/$B$2) -> 0.97402651 | F72: =POWER($C$2,$C72/$B$2) -> 0.97402651 | G72: =POWER($C$2,$D72/$B$2) -> 0.97402651 | H72: =POWER($C$3,$B72/$B$3) -> 0.98692782 | I72: =POWER($C$3,$C72/$B$3) -> 0.98692782 | J72: =POWER($C$3,$D72/$B$3) -> 0.98692782 | K72: =POWER($C$4,$B72/$B$4) -> 0.99126611 | L72: =POWER($C$4,$C72/$B$4) -> 0.99126611 | M72: =POWER($C$4,$D72/$B$4) -> 0.99126611 | N72: =POWER($C$5,$B72/$B$5) -> 0.99344241 | O72: =POWER($C$5,$C72/$B$5) -> 0.99344241 | P72: =POWER($C$5,$D72/$B$5) -> 0.99344241 | Q72: =POWER($C$6,$B72/$B$6) -> 0.99475048 | R72: =POWER($C$6,$C72/$B$6) -> 0.99475048 | S72: =POWER($C$6,$D72/$B$6) -> 0.99475048 | T72: =POWER($C$7,$B72/$B$7) -> 0.99562348 | U72: =POWER($C$7,$C72/$B$7) -> 0.99562348 | V72: =POWER($C$7,$D72/$B$7) -> 0.99562348
A73: =Tabelle2!A89 -> Desmodus | B73: =Tabelle2!$N89+(B$11*Tabelle2!$O89) -> 1760 | C73: =Tabelle2!$N89+(C$11*Tabelle2!$O89) -> 9600 | D73: =Tabelle2!$N89+(D$11*Tabelle2!$O89) -> 25600 | E73: =POWER($C$2,$B73/$B$2) -> 0.94780338 | F73: =POWER($C$2,$C73/$B$2) -> 0.74646362 | G73: =POWER($C$2,$D73/$B$2) -> 0.45851801 | H73: =POWER($C$3,$B73/$B$3) -> 0.97355194 | I73: =POWER($C$3,$C73/$B$3) -> 0.86398126 | J73: =POWER($C$3,$D73/$B$3) -> 0.67713958 | K73: =POWER($C$4,$B73/$B$4) -> 0.98228931 | L73: =POWER($C$4,$C73/$B$4) -> 0.90713004 | M73: =POWER($C$4,$D73/$B$4) -> 0.77111437 | N73: =POWER($C$5,$B73/$B$5) -> 0.98668736 | O73: =POWER($C$5,$C73/$B$5) -> 0.92950592 | P73: =POWER($C$5,$D73/$B$5) -> 0.82288491 | Q73: =POWER($C$6,$B73/$B$6) -> 0.98933563 | R73: =POWER($C$6,$C73/$B$6) -> 0.94319552 | S73: =POWER($C$6,$D73/$B$6) -> 0.85560099 | T73: =POWER($C$7,$B73/$B$7) -> 0.99110509 | U73: =POWER($C$7,$C73/$B$7) -> 0.95243375 | V73: =POWER($C$7,$D73/$B$7) -> 0.87813118
A74: =Tabelle2!A90 -> Dilophosaur | B74: =Tabelle2!$N90+(B$11*Tabelle2!$O90) -> 495 | C74: =Tabelle2!$N90+(C$11*Tabelle2!$O90) -> 2700 | D74: =Tabelle2!$N90+(D$11*Tabelle2!$O90) -> 7200 | E74: =POWER($C$2,$B74/$B$2) -> 0.98503579 | F74: =POWER($C$2,$C74/$B$2) -> 0.92105101 | G74: =POWER($C$2,$D74/$B$2) -> 0.8030757 | H74: =POWER($C$3,$B74/$B$3) -> 0.99248969 | I74: =POWER($C$3,$C74/$B$3) -> 0.95971402 | J74: =POWER($C$3,$D74/$B$3) -> 0.89614491 | K74: =POWER($C$4,$B74/$B$4) -> 0.99498684 | L74: =POWER($C$4,$C74/$B$4) -> 0.97295905 | M74: =POWER($C$4,$D74/$B$4) -> 0.92950592 | N74: =POWER($C$5,$B74/$B$5) -> 0.99623777 | O74: =POWER($C$5,$C74/$B$5) -> 0.97964995 | P74: =POWER($C$5,$D74/$B$5) -> 0.94664931 | Q74: =POWER($C$6,$B74/$B$6) -> 0.99698908 | R74: =POWER($C$6,$C74/$B$6) -> 0.98368656 | S74: =POWER($C$6,$D74/$B$6) -> 0.95708674 | T74: =POWER($C$7,$B74/$B$7) -> 0.99749027 | U74: =POWER($C$7,$C74/$B$7) -> 0.98638686 | V74: =POWER($C$7,$D74/$B$7) -> 0.96410888
...
